<?xml version="1.0" ?>
<robot
  name="ugv_rover">
  <link name="base_footprint"></link>
  <link
    name="base_link">
    <inertial>
      <origin
        xyz="-0.000460087791654118 -6.50856019576702E-10 -0.0147959620149623"
        rpy="0 0 0" />
      <mass
        value="2.78375064359473" />
      <inertia
        ixx="0.00651567554169617"
        ixy="-5.86655425789789E-13"
        ixz="3.77886436056975E-05"
        iyy="0.00933991752413667"
        iyz="-2.53116742521487E-11"
        izz="0.0121583506563461" />
    </inertial>
    <visual>
      <origin
        xyz="0 0 0"
        rpy="0 0 0" />
      <geometry>
        <mesh
          filename="package://rover_description/meshes/base_link.stl" />
      </geometry>
      <material
        name="">
        <color
          rgba="0.752941176470588 0.752941176470588 0.752941176470588 1" />
      </material>
    </visual>
    <collision>
      <origin
        xyz="0 0 0"
        rpy="0 0 0" />
      <geometry>
        <mesh
          filename="package://rover_description/meshes/base_link.stl" />
      </geometry>
    </collision>
  </link>

  <joint name="base_joint" type="fixed">
    <parent link="base_footprint"/>
    <child link="base_link"/>
    <origin xyz="0.000460087791654118 6.50856019576702E-10 0.08" rpy="0 0 0"/> 
  </joint>
  
  <link name="base_imu_link"> 
      <origin xyz="0 0 0" rpy="0 0 0"/> 
  </link>
  
  <joint name="imu_joint" type="fixed">
      <parent link="base_link" />
      <child link="base_imu_link" />
      <origin xyz="0 0 0" rpy="0 0 0"/>
  </joint>

  <link
    name="left_up_wheel_link">
    <inertial>
      <origin
        xyz="1.38777878078145E-17 1.38777878078145E-17 0"
        rpy="1.5708 0 0" />
      <mass
        value="0.207085933743005" />
      <inertia
        ixx="0.000116541923504163"
        ixy="-1.59309191113245E-55"
        ixz="-3.43238458333891E-37"
        iyy="0.000170742352371108"
        iyz="-3.6165187302327E-37"
        izz="0.000116541923504163" />
    </inertial>
    <visual>
      <origin
        xyz="0 0 0"
        rpy="1.5708 0 0" />
      <geometry>
        <mesh
          filename="package://rover_description/meshes/left_up_wheel_link.stl" />
      </geometry>
      <material
        name="">
        <color
          rgba="0.627450980392157 0.627450980392157 0.627450980392157 1" />
      </material>
    </visual>
    <collision>
      <origin
        xyz="0 0 0"
        rpy="1.5708 0 0" />
      <geometry>
        <mesh
          filename="package://rover_description/meshes/left_up_wheel_link.stl" />
      </geometry>
    </collision>
  </link>
  <joint
    name="left_up_wheel_link_joint"
    type="continuous">
    <origin
      xyz="0.0855 0.08726 -0.041212"
      rpy="1.5708 0 0" />
    <parent
      link="base_link" />
    <child
      link="left_up_wheel_link" />
    <axis
      xyz="0 0 -1" />
  </joint>
  <link
    name="left_down_wheel_link">
    <inertial>
      <origin
        xyz="0 1.38777878078145E-17 0"
        rpy="1.5708 0 0" />
      <mass
        value="0.207085933743005" />
      <inertia
        ixx="0.000116541923504163"
        ixy="-1.59309191113245E-55"
        ixz="-3.43238458333891E-37"
        iyy="0.000170742352371108"
        iyz="-3.6165187302327E-37"
        izz="0.000116541923504163" />
    </inertial>
    <visual>
      <origin
        xyz="0 0 0"
        rpy="1.5708 0 0" />
      <geometry>
        <mesh
          filename="package://rover_description/meshes/left_down_wheel_link.stl" />
      </geometry>
      <material
        name="">
        <color
          rgba="0.627450980392157 0.627450980392157 0.627450980392157 1" />
      </material>
    </visual>
    <collision>
      <origin
        xyz="0 0 0"
        rpy="1.5708 0 0" />
      <geometry>
        <mesh
          filename="package://rover_description/meshes/left_down_wheel_link.stl" />
      </geometry>
    </collision>
  </link>
  <joint
    name="left_down_wheel_link_joint"
    type="continuous">
    <origin
      xyz="-0.0854999999999981 0.0872599990000038 -0.0412119912691592"
      rpy="1.5708 0 0" />
    <parent
      link="base_link" />
    <child
      link="left_down_wheel_link" />
    <axis
      xyz="0 0 -1" />
  </joint>
  <link
    name="right_up_wheel_link">
    <inertial>
      <origin
        xyz="1.38777878078145E-17 -1.38777878078145E-17 0"
        rpy="1.5708 0 0" />
      <mass
        value="0.207085933743005" />
      <inertia
        ixx="0.000116541923504163"
        ixy="-1.59309191113245E-55"
        ixz="-3.43238458333891E-37"
        iyy="0.000170742352371108"
        iyz="-3.6165187302327E-37"
        izz="0.000116541923504163" />
    </inertial>
    <visual>
      <origin
        xyz="0 0 0"
        rpy="1.5708 0 0" />
      <geometry>
        <mesh
          filename="package://rover_description/meshes/right_up_wheel_link.stl" />
      </geometry>
      <material
        name="">
        <color
          rgba="0.627450980392157 0.627450980392157 0.627450980392157 1" />
      </material>
    </visual>
    <collision>
      <origin
        xyz="0 0 0"
        rpy="1.5708 0 0" />
      <geometry>
        <mesh
          filename="package://rover_description/meshes/right_up_wheel_link.stl" />
      </geometry>
    </collision>
  </link>
  <joint
    name="right_up_wheel_link_joint"
    type="continuous">
    <origin
      xyz="0.0854999999999989 -0.0872600009999962 -0.0412119912691588"
      rpy="1.5708 0 0" />
    <parent
      link="base_link" />
    <child
      link="right_up_wheel_link" />
    <axis
      xyz="0 0 -1" />
  </joint>
  <link
    name="right_down_wheel_link">
    <inertial>
      <origin
        xyz="0 -1.38777878078145E-17 0"
        rpy="1.5708 0 0" />
      <mass
        value="0.207085933743005" />
      <inertia
        ixx="0.000116541923504163"
        ixy="-1.59309191113245E-55"
        ixz="-3.43238458333891E-37"
        iyy="0.000170742352371108"
        iyz="-3.6165187302327E-37"
        izz="0.000116541923504163" />
    </inertial>
    <visual>
      <origin
        xyz="0 0 0"
        rpy="1.5708 0 0" />
      <geometry>
        <mesh
          filename="package://rover_description/meshes/right_down_wheel_link.stl" />
      </geometry>
      <material
        name="">
        <color
          rgba="0.627450980392157 0.627450980392157 0.627450980392157 1" />
      </material>
    </visual>
    <collision>
      <origin
        xyz="0 0 0"
        rpy="1.5708 0 0" />
      <geometry>
        <mesh
          filename="package://rover_description/meshes/right_down_wheel_link.stl" />
      </geometry>
    </collision>
  </link>
  <joint
    name="right_down_wheel_link_joint"
    type="continuous">
    <origin
      xyz="-0.0854999999999981 -0.0872600009999962 -0.0412119912691594"
      rpy="1.5708 0 0" />
    <parent
      link="base_link" />
    <child
      link="right_down_wheel_link" />
    <axis
      xyz="0 0 -1" />
  </joint>
  
  <link
    name="pt_camera_link">
    <inertial>
      <origin
        xyz="0.00630730338217479 -7.90865732935165E-18 0.000950308188413934"
        rpy="0 -1.5708 1.5708" />
      <mass
        value="0.00623651844028495" />
      <inertia
        ixx="5.11295942352593E-07"
        ixy="3.46495200123478E-22"
        ixz="-4.00917493406375E-08"
        iyy="3.99078324787848E-07"
        iyz="1.31404415819798E-22"
        izz="4.02518684222241E-07" />
    </inertial>
    <visual>
      <origin
        xyz="0 0 0"
        rpy="0 -1.5708 1.5708" />
      <geometry>
        <mesh
          filename="package://rover_description/meshes/pt_camera_link.stl" />
      </geometry>
      <material
        name="">
        <color
          rgba="0.627450980392157 0.627450980392157 0.627450980392157 1" />
      </material>
    </visual>
    <collision>
      <origin
        xyz="0 0 0"
        rpy="0 -1.5708 1.5708" />
      <geometry>
        <mesh
          filename="package://rover_description/meshes/pt_camera_link.stl" />
      </geometry>
    </collision>
  </link>
  <joint
    name="camera_joint"
    type="fixed">
    <origin
      xyz="0.070 0 0.025"
      rpy="0 1.5708 0" />
    <parent
      link="base_link" />
    <child
      link="pt_camera_link" />
  </joint>
  
  <link name="base_lidar_link">
    <inertial>
      <origin xyz="0 0 0" rpy="0 0 0"/>
      <mass value="0.125"/>
      <inertia ixx="0.001" ixy="0" ixz="0" iyy="0.001" iyz="0" izz="0.001"/>
    </inertial>
    <visual>
      <origin xyz="0 0 0" rpy="0 0 0"/>
      <geometry>
        <mesh filename="package://rover_description/meshes/base_lidar_link.stl"/>
      </geometry>
      <material name="black">
        <color rgba="0.0 0.0 0.0 1.0"/>
      </material>
    </visual>
    <collision>
      <origin xyz="0 0 0" rpy="0 0 0"/>
      <geometry>
        <cylinder radius="0.025" length="0.035"/>
      </geometry>
    </collision>
  </link>

  <joint name="base_lidar_joint" type="fixed">
    <parent link="base_link"/>
    <child link="base_lidar_link"/>
    <origin xyz="0.045 0.0 0.037" rpy="0 0 0"/>
  </joint>
  
  <link name="laser_frame">
    <!-- Empty link for laser scan data -->
  </link>

  <joint name="laser_joint" type="fixed">
    <parent link="base_lidar_link"/>
    <child link="laser_frame"/>
    <origin xyz="0 0 0.0175" rpy="0 0 0"/>  <!-- Adjust height if needed -->
  </joint>

</robot>